Workbook

Sheet Study Plan
A1: # | B1: Phase | C1: Topic | D1: Sub-Pattern | E1: Topic Order# | F1: Priority | G1: Problem | H1: Pattern / Approach Note | I1: Status | J1: Needs Revisit | K1: Date Solved | L1: Notes | M1: LeetCode Link | N1: Walkthrough
A2: 1 | B2: Phase 1 · Foundations | C2: 📦 Arrays & Matrices | D2: Warm-ups — basic scan and indexing | E2: 1 | F2: Must-do | G2: Concatenation of Array | H2: Re-index into a 2×N array. | I2: Solved | K2: 46165 | M2: =HYPERLINK("https://leetcode.com/problems/concatenation-of-array/","Solve on LeetCode ↗") | N2: =HYPERLINK("https://github.com/Prateek-5/question-bank/blob/main/DSA/Topics/Arrays_and_Matrices/learn/Concatenation_of_Array.md","View Walkthrough ↗")
A3: 2 | B3: Phase 1 · Foundations | C3: 📦 Arrays & Matrices | D3: Warm-ups — basic scan and indexing | E3: 2 | F3: Must-do | G3: Fizz Buzz | H3: Branching on divisibility; cleanest hello-world. | I3: Solved | K3: 46165 | M3: =HYPERLINK("https://leetcode.com/problems/fizz-buzz/","Solve on LeetCode ↗") | N3: =HYPERLINK("https://github.com/Prateek-5/question-bank/blob/main/DSA/Topics/Arrays_and_Matrices/learn/Fizz_Buzz.md","View Walkthrough ↗")
A4: 3 | B4: Phase 1 · Foundations | C4: 📦 Arrays & Matrices | D4: Warm-ups — basic scan and indexing | E4: 3 | G4: Maximum Number of Words Found in Sentences | H4: Per-row max via split. | I4: Solved | K4: 46165 | M4: =HYPERLINK("https://leetcode.com/problems/maximum-number-of-words-found-in-sentences/","Solve on LeetCode ↗") | N4: =HYPERLINK("https://github.com/Prateek-5/question-bank/blob/main/DSA/Topics/Arrays_and_Matrices/learn/Maximum_Number_of_Words_Found_in_Sentences.md","View Walkthrough ↗")
A5: 4 | B5: Phase 1 · Foundations | C5: 📦 Arrays & Matrices | D5: Matrix access — 2D indexing | E5: 4 | F5: Must-do | G5: Matrix Diagonal Sum | H5: Main + anti-diagonal; handle odd-size middle. | I5: Solved | J5: Yes | K5: 46165 | M5: =HYPERLINK("https://leetcode.com/problems/matrix-diagonal-sum/","Solve on LeetCode ↗") | N5: =HYPERLINK("https://github.com/Prateek-5/question-bank/blob/main/DSA/Topics/Arrays_and_Matrices/learn/Matrix_Diagonal_Sum.md","View Walkthrough ↗")
A6: 5 | B6: Phase 1 · Foundations | C6: 📦 Arrays & Matrices | D6: Matrix access — 2D indexing | E6: 5 | F6: Must-do | G6: Spiral Matrix II | H6: Boundary-walking simulation with four directions. | I6: Skipped | M6: =HYPERLINK("https://leetcode.com/problems/spiral-matrix-ii/","Solve on LeetCode ↗") | N6: =HYPERLINK("https://github.com/Prateek-5/question-bank/blob/main/DSA/Topics/Arrays_and_Matrices/learn/Spiral_Matrix_II.md","View Walkthrough ↗")
A7: 6 | B7: Phase 1 · Foundations | C7: 📦 Arrays & Matrices | D7: Sweep / observation | E7: 6 | G7: Maximum Gap | H7: Bucket sort to beat sort's O(n log n). Senior signal. | I7: Skipped | M7: =HYPERLINK("https://leetcode.com/problems/maximum-gap/","Solve on LeetCode ↗") | N7: =HYPERLINK("https://github.com/Prateek-5/question-bank/blob/main/DSA/Topics/Arrays_and_Matrices/learn/Maximum_Gap.md","View Walkthrough ↗")
A8: 7 | B8: Phase 1 · Foundations | C8: 📦 Arrays & Matrices | D8: Sweep / observation | E8: 7 | G8: Total Hamming Distance | H8: Bit-by-bit contribution; O(n × 32) not O(n²). | I8: Solved | J8: Yes | K8: 46166 | M8: =HYPERLINK("https://leetcode.com/problems/total-hamming-distance/","Solve on LeetCode ↗") | N8: =HYPERLINK("https://github.com/Prateek-5/question-bank/blob/main/DSA/Topics/Arrays_and_Matrices/learn/Total_Hamming_Distance.md","View Walkthrough ↗")
A9: 8 | B9: Phase 1 · Foundations | C9: 📦 Arrays & Matrices | D9: Sweep / observation | E9: 8 | G9: Maximum Absolute Value Expression | H9: Math trick to remove absolute values via sign enumeration. | I9: Skipped | M9: =HYPERLINK("https://leetcode.com/problems/maximum-of-absolute-value-expression/","Solve on LeetCode ↗") | N9: =HYPERLINK("https://github.com/Prateek-5/question-bank/blob/main/DSA/Topics/Arrays_and_Matrices/learn/Maximum_Absolute_Value_Expression.md","View Walkthrough ↗")
A10: 9 | B10: Phase 1 · Foundations | C10: 📦 Arrays & Matrices | D10: Classic finale | E10: 9 | F10: Must-do | G10: Trapping Rain Water | H10: Two-pointer or precomputed L/R max. THE classic. | I10: Solved | J10: Yes | K10: 46166 | M10: =HYPERLINK("https://leetcode.com/problems/trapping-rain-water/","Solve on LeetCode ↗") | N10: =HYPERLINK("https://github.com/Prateek-5/question-bank/blob/main/DSA/Topics/Arrays_and_Matrices/learn/Trapping_Rain_Water.md","View Walkthrough ↗")
A11: 10 | B11: Phase 1 · Foundations | C11: 📊 1-D & 2-D Arrays | D11: Prefix sum — 1D | E11: 1 | F11: Must-do | G11: Running Sum of 1D Array | H11: Literally the prefix-sum array. The reflex starts here. | I11: Solved | K11: 46166 | M11: =HYPERLINK("https://leetcode.com/problems/running-sum-of-1d-array/","Solve on LeetCode ↗") | N11: =HYPERLINK("https://github.com/Prateek-5/question-bank/blob/main/DSA/Topics/1_D_and_2_D_Arrays/learn/Running_Sum_of_1D_Array.md","View Walkthrough ↗")
A12: 11 | B12: Phase 1 · Foundations | C12: 📊 1-D & 2-D Arrays | D12: 2D scan (no prefix yet) | E12: 2 | F12: Must-do | G12: Richest Customer Wealth | H12: Row sums + max. | I12: Solved | K12: 46166 | M12: =HYPERLINK("https://leetcode.com/problems/richest-customer-wealth/","Solve on LeetCode ↗") | N12: =HYPERLINK("https://github.com/Prateek-5/question-bank/blob/main/DSA/Topics/1_D_and_2_D_Arrays/learn/Richest_Customer_Wealth.md","View Walkthrough ↗")
A13: 12 | B13: Phase 1 · Foundations | C13: 📊 1-D & 2-D Arrays | D13: 2D scan (no prefix yet) | E13: 3 | G13: Special Positions in a Binary Matrix | H13: Precompute row + column counts. | I13: Solved | J13: Yes | K13: 46166 | M13: =HYPERLINK("https://leetcode.com/problems/special-positions-in-a-binary-matrix/","Solve on LeetCode ↗") | N13: =HYPERLINK("https://github.com/Prateek-5/question-bank/blob/main/DSA/Topics/1_D_and_2_D_Arrays/learn/Special_Positions_in_a_Binary_Matrix.md","View Walkthrough ↗")
A14: 13 | B14: Phase 1 · Foundations | C14: 📊 1-D & 2-D Arrays | D14: Index mapping | E14: 4 | F14: Must-do | G14: Convert 1D Array Into 2D Array | H14: `i = k/cols, j = k%cols`. | I14: Solved | J14: Yes | K14: 46167 | M14: =HYPERLINK("https://leetcode.com/problems/convert-1d-array-into-2d-array/","Solve on LeetCode ↗") | N14: =HYPERLINK("https://github.com/Prateek-5/question-bank/blob/main/DSA/Topics/1_D_and_2_D_Arrays/learn/Convert_1D_Array_Into_2D_Array.md","View Walkthrough ↗")
A15: 14 | B15: Phase 1 · Foundations | C15: 📊 1-D & 2-D Arrays | D15: Greedy on arrays | E15: 5 | G15: Max Chunks To Make Sorted | H15: Running max equals current index → chunk boundary. | I15: Skipped | M15: =HYPERLINK("https://leetcode.com/problems/max-chunks-to-make-sorted/","Solve on LeetCode ↗") | N15: =HYPERLINK("https://github.com/Prateek-5/question-bank/blob/main/DSA/Topics/1_D_and_2_D_Arrays/learn/Max_Chunks_To_Make_Sorted.md","View Walkthrough ↗")
A16: 15 | B16: Phase 1 · Foundations | C16: 📊 1-D & 2-D Arrays | D16: Contribution / submatrix sums | E16: 6 | G16: Sum of All Submatrices Odd Length Subarrays | H16: Each element's contribution = (number of subarrays containing it). Classic counting trick. | I16: Skipped | M16: =HYPERLINK("https://leetcode.com/problems/sum-of-all-odd-length-subarrays/","Solve on LeetCode ↗") | N16: =HYPERLINK("https://github.com/Prateek-5/question-bank/blob/main/DSA/Topics/1_D_and_2_D_Arrays/learn/Sum_of_All_Submatrices_Odd_Length_Subarrays.md","View Walkthrough ↗")
A17: 16 | B17: Phase 1 · Foundations | C17: 📊 1-D & 2-D Arrays | D17: 2D prefix sum | E17: 7 | F17: Must-do | G17: Range Sum Query 2D Immutable | H17: 2D prefix sum via inclusion-exclusion. | I17: Skipped | M17: =HYPERLINK("https://leetcode.com/problems/range-sum-query-2d-immutable/","Solve on LeetCode ↗") | N17: =HYPERLINK("https://github.com/Prateek-5/question-bank/blob/main/DSA/Topics/1_D_and_2_D_Arrays/learn/Range_Sum_Query_2D_Immutable.md","View Walkthrough ↗")
A18: 17 | B18: Phase 1 · Foundations | C18: 📊 1-D & 2-D Arrays | D18: Sorted 2D search | E18: 8 | F18: Must-do | G18: Search a 2D Matrix II | H18: Staircase search from top-right (or bottom-left). O(n+m). | I18: Skipped | M18: =HYPERLINK("https://leetcode.com/problems/search-a-2d-matrix-ii/","Solve on LeetCode ↗") | N18: =HYPERLINK("https://github.com/Prateek-5/question-bank/blob/main/DSA/Topics/1_D_and_2_D_Arrays/learn/Search_a_2D_Matrix_II.md","View Walkthrough ↗")
A19: 18 | B19: Phase 1 · Foundations | C19: 🔍 Two Pointers | D19: Sorted-array opposing pointers | E19: 1 | F19: Must-do | G19: Two Sum II Input Array Is Sorted | H19: The template. `lo, hi`, move based on sum vs target. | I19: Solved | K19: 46054 | M19: =HYPERLINK("https://leetcode.com/problems/two-sum-ii-input-array-is-sorted/","Solve on LeetCode ↗") | N19: =HYPERLINK("https://github.com/Prateek-5/question-bank/blob/main/DSA/Topics/Two_Pointers/learn/Two_Sum_II_Input_Array_Is_Sorted.md","View Walkthrough ↗")
A20: 19 | B20: Phase 1 · Foundations | C20: 🔍 Two Pointers | D20: Sorted-array opposing pointers | E20: 2 | F20: Must-do | G20: Container With Most Water | H20: Same shape, different metric. Move the shorter side. | I20: Solved | K20: 46053 | M20: =HYPERLINK("https://leetcode.com/problems/container-with-most-water/","Solve on LeetCode ↗") | N20: =HYPERLINK("https://github.com/Prateek-5/question-bank/blob/main/DSA/Topics/Two_Pointers/learn/Container_With_Most_Water.md","View Walkthrough ↗")
A21: 20 | B21: Phase 1 · Foundations | C21: 🔍 Two Pointers | D21: k-sum family | E21: 3 | F21: Must-do | G21: 3Sum | H21: Fix one, two-pointer the rest. Dedup carefully. | I21: Solved | J21: Yes | K21: 46054 | M21: =HYPERLINK("https://leetcode.com/problems/3sum/","Solve on LeetCode ↗") | N21: =HYPERLINK("https://github.com/Prateek-5/question-bank/blob/main/DSA/Topics/Two_Pointers/learn/3Sum.md","View Walkthrough ↗")
A22: 21 | B22: Phase 1 · Foundations | C22: 🔍 Two Pointers | D22: Pair problems with constraints | E22: 4 | G22: Minimize Maximum Pair Sum in Array | H22: Sort + pair from ends. | I22: Not Started | J22: Yes | M22: =HYPERLINK("https://leetcode.com/problems/minimize-maximum-pair-sum-in-array/description/","Solve on LeetCode ↗") | N22: =HYPERLINK("https://github.com/Prateek-5/question-bank/blob/main/DSA/Topics/Two_Pointers/learn/Minimize_Maximum_Pair_Sum_in_Array.md","View Walkthrough ↗")
A23: 22 | B23: Phase 1 · Foundations | C23: 🔍 Two Pointers | D23: Pair problems with constraints | E23: 5 | G23: K diff Pairs in an Array | H23: Sorted two-pointer with difference target. | I23: Not Started | J23: Yes | M23: =HYPERLINK("https://leetcode.com/problems/k-diff-pairs-in-an-array/","Solve on LeetCode ↗") | N23: =HYPERLINK("https://github.com/Prateek-5/question-bank/blob/main/DSA/Topics/Two_Pointers/learn/K_diff_Pairs_in_an_Array.md","View Walkthrough ↗")
A24: 23 | B24: Phase 1 · Foundations | C24: 🔍 Two Pointers | D24: Two-pointer variant of a classic | E24: 6 | G24: Trapping Rain Water | H24: Same problem as in `Arrays_and_Matrices/`, but solved with O(1) extra space via two pointers. Compare to the L/R precomputed version. | I24: Solved | K24: 46053 | M24: =HYPERLINK("https://leetcode.com/problems/trapping-rain-water/","Solve on LeetCode ↗") | N24: =HYPERLINK("https://github.com/Prateek-5/question-bank/blob/main/DSA/Topics/Two_Pointers/learn/Trapping_Rain_Water.md","View Walkthrough ↗")
A25: 24 | B25: Phase 1 · Foundations | C25: 🔍 Two Pointers | D25: Multi-pointer DP-flavored | E25: 7 | G25: Ugly Number II | H25: Three pointers tracking ×2, ×3, ×5 progress. Atypical but illuminating. | I25: Not Started | J25: Yes | M25: =HYPERLINK("https://leetcode.com/problems/ugly-number-ii/","Solve on LeetCode ↗") | N25: =HYPERLINK("https://github.com/Prateek-5/question-bank/blob/main/DSA/Topics/Two_Pointers/learn/Ugly_Number_II.md","View Walkthrough ↗")
A26: 25 | B26: Phase 1 · Foundations | C26: 🧮 Hashing / Sliding Window | D26: Hash for frequency | E26: 1 | F26: Must-do | G26: Valid Anagram | H26: Char count map. | I26: Solved | J26: Yes | K26: 46168 | M26: =HYPERLINK("https://leetcode.com/problems/valid-anagram/","Solve on LeetCode ↗") | N26: =HYPERLINK("https://github.com/Prateek-5/question-bank/blob/main/DSA/Topics/Hashing_Sliding_Window/learn/Valid_Anagram.md","View Walkthrough ↗")
A27: 26 | B27: Phase 1 · Foundations | C27: 🧮 Hashing / Sliding Window | D27: Multi-key hash | E27: 2 | F27: Must-do | G27: Valid Sudoku | H27: Three sets per category (row, col, box). | I27: Solved | J27: Yes | K27: 46168 | M27: =HYPERLINK("https://leetcode.com/problems/valid-sudoku/","Solve on LeetCode ↗") | N27: =HYPERLINK("https://github.com/Prateek-5/question-bank/blob/main/DSA/Topics/Hashing_Sliding_Window/learn/Valid_Sudoku.md","View Walkthrough ↗")
A28: 27 | B28: Phase 1 · Foundations | C28: 🧮 Hashing / Sliding Window | D28: Prefix sum + hash (subarray-sum) | E28: 3 | F28: Must-do | G28: Subarray Sum Equals K | H28: `count[prefix - k]`. THE canonical pattern. | I28: Skipped | M28: =HYPERLINK("https://leetcode.com/problems/subarray-sum-equals-k/","Solve on LeetCode ↗") | N28: =HYPERLINK("https://github.com/Prateek-5/question-bank/blob/main/DSA/Topics/Hashing_Sliding_Window/learn/Subarray_Sum_Equals_K.md","View Walkthrough ↗")
A29: 28 | B29: Phase 1 · Foundations | C29: 🧮 Hashing / Sliding Window | D29: Prefix sum + hash (subarray-sum) | E29: 4 | G29: Maximum Size Subarray Sum Equals K | H29: Variant: track first occurrence for max length. | I29: Skipped | M29: =HYPERLINK("https://leetcode.com/problems/maximum-size-subarray-sum-equals-k/","Solve on LeetCode ↗") | N29: =HYPERLINK("https://github.com/Prateek-5/question-bank/blob/main/DSA/Topics/Hashing_Sliding_Window/learn/Maximum_Size_Subarray_Sum_Equals_K.md","View Walkthrough ↗")
A30: 29 | B30: Phase 1 · Foundations | C30: 🧮 Hashing / Sliding Window | D30: Prefix sum + hash (subarray-sum) | E30: 5 | G30: Largest Subarray With 0 Sum | H30: Same idea, target = 0. | I30: Skipped | M30: =HYPERLINK("https://www.geeksforgeeks.org/problems/largest-subarray-with-0-sum/1","Solve on LeetCode ↗") | N30: =HYPERLINK("https://github.com/Prateek-5/question-bank/blob/main/DSA/Topics/Hashing_Sliding_Window/learn/Largest_Subarray_With_0_Sum.md","View Walkthrough ↗")
A31: 30 | B31: Phase 1 · Foundations | C31: 🧮 Hashing / Sliding Window | D31: Set-based | E31: 6 | F31: Must-do | G31: Longest Consecutive Sequence | H31: Build set, start only at run-beginnings (where `n-1` not in set). O(n). | I31: Skipped | M31: =HYPERLINK("https://leetcode.com/problems/longest-consecutive-sequence/","Solve on LeetCode ↗") | N31: =HYPERLINK("https://github.com/Prateek-5/question-bank/blob/main/DSA/Topics/Hashing_Sliding_Window/learn/Longest_Consecutive_Sequence.md","View Walkthrough ↗")
A32: 31 | B32: Phase 1 · Foundations | C32: 🧮 Hashing / Sliding Window | D32: Sliding window — variable size | E32: 7 | F32: Must-do | G32: Longest Substring Without Repeating Characters | H32: Window + last-index map. | I32: Skipped | M32: =HYPERLINK("https://leetcode.com/problems/longest-substring-without-repeating-characters/","Solve on LeetCode ↗") | N32: =HYPERLINK("https://github.com/Prateek-5/question-bank/blob/main/DSA/Topics/Hashing_Sliding_Window/learn/Longest_Substring_Without_Repeating_Characters.md","View Walkthrough ↗")
A33: 32 | B33: Phase 1 · Foundations | C33: 🧮 Hashing / Sliding Window | D33: Sliding window — variable size | E33: 8 | G33: Minimum Window Substring | H33: Window + need-count + satisfied counter. The hardest window template. | I33: Skipped | M33: =HYPERLINK("https://leetcode.com/problems/minimum-window-substring/","Solve on LeetCode ↗") | N33: =HYPERLINK("https://github.com/Prateek-5/question-bank/blob/main/DSA/Topics/Hashing_Sliding_Window/learn/Minimum_Window_Substring.md","View Walkthrough ↗")
A34: 33 | B34: Phase 1 · Foundations | C34: 🧮 Hashing / Sliding Window | D34: Hash + clever insight | E34: 9 | G34: Palindrome Pairs | H34: Map word → index; for each word, check splits where one side is palindrome and other reversed exists. | I34: Skipped | M34: =HYPERLINK("https://leetcode.com/problems/palindrome-pairs/","Solve on LeetCode ↗") | N34: =HYPERLINK("https://github.com/Prateek-5/question-bank/blob/main/DSA/Topics/Hashing_Sliding_Window/learn/Palindrome_Pairs.md","View Walkthrough ↗")
A35: 34 | B35: Phase 1 · Foundations | C35: 🧮 Hashing / Sliding Window | D35: Hash + clever insight | E35: 10 | G35: Max Points on a Line | H35: Slope hash; tricky equal-points and vertical-line edge cases. | I35: Skipped | M35: =HYPERLINK("https://leetcode.com/problems/max-points-on-a-line/","Solve on LeetCode ↗") | N35: =HYPERLINK("https://github.com/Prateek-5/question-bank/blob/main/DSA/Topics/Hashing_Sliding_Window/learn/Max_Points_on_a_Line.md","View Walkthrough ↗")
A36: 35 | B36: Phase 1 · Foundations | C36: 📚 Stack | D36: Balanced parens / string simulation | E36: 1 | F36: Must-do | G36: Valid Parentheses | H36: The hello-world of stacks. Push openers, match on closers. | I36: Solved | K36: 46168 | M36: =HYPERLINK("https://leetcode.com/problems/valid-parentheses/","Solve on LeetCode ↗") | N36: =HYPERLINK("https://github.com/Prateek-5/question-bank/blob/main/DSA/Topics/Stack/learn/Valid_Parentheses.md","View Walkthrough ↗")
A37: 36 | B37: Phase 1 · Foundations | C37: 📚 Stack | D37: Balanced parens / string simulation | E37: 2 | G37: Remove Outermost Parentheses | H37: Depth counter (a stack of size 1 conceptually). | I37: Skipped | M37: =HYPERLINK("https://leetcode.com/problems/remove-outermost-parentheses/","Solve on LeetCode ↗") | N37: =HYPERLINK("https://github.com/Prateek-5/question-bank/blob/main/DSA/Topics/Stack/learn/Remove_Outermost_Parentheses.md","View Walkthrough ↗")
A38: 37 | B38: Phase 1 · Foundations | C38: 📚 Stack | D38: Balanced parens / string simulation | E38: 3 | F38: Must-do | G38: Remove All Adjacent Duplicates in String | H38: Stack of chars; pop on match. | I38: Solved | K38: 46168 | M38: =HYPERLINK("https://leetcode.com/problems/remove-all-adjacent-duplicates-in-string/","Solve on LeetCode ↗") | N38: =HYPERLINK("https://github.com/Prateek-5/question-bank/blob/main/DSA/Topics/Stack/learn/Remove_All_Adjacent_Duplicates_in_String.md","View Walkthrough ↗")
A39: 38 | B39: Phase 1 · Foundations | C39: 📚 Stack | D39: Stack design | E39: 4 | F39: Must-do | G39: Min Stack | H39: Auxiliary stack tracking min so far. O(1) min. | I39: Skipped | M39: =HYPERLINK("https://leetcode.com/problems/min-stack/","Solve on LeetCode ↗") | N39: =HYPERLINK("https://github.com/Prateek-5/question-bank/blob/main/DSA/Topics/Stack/learn/Min_Stack.md","View Walkthrough ↗")
A40: 39 | B40: Phase 1 · Foundations | C40: 📚 Stack | D40: Expression eval | E40: 5 | G40: Baseball Game | H40: Stack of scores; operations transform top elements. | I40: Solved | J40: Yes | K40: 46168 | M40: =HYPERLINK("https://leetcode.com/problems/baseball-game/","Solve on LeetCode ↗") | N40: =HYPERLINK("https://github.com/Prateek-5/question-bank/blob/main/DSA/Topics/Stack/learn/Baseball_Game.md","View Walkthrough ↗")
...

Sheet Overall Progress
A1: 📊 Overall Progress Dashboard
A2: Every figure below is a live formula against 'Study Plan' — change a Status or Needs Revisit flag there and this whole dashboard recalculates instantly. A problem can be Solved AND flagged Needs Revisit at the same time.
A4: TOTAL PROBLEMS | E4: SOLVED | I4: IN PROGRESS | M4: NOT STARTED
A5: =COUNTA('Study Plan'!$G$2:$G$227) | E5: =COUNTIF('Study Plan'!$I$2:$I$227,"Solved") | I5: =COUNTIF('Study Plan'!$I$2:$I$227,"In Progress") | M5: =COUNTIF('Study Plan'!$I$2:$I$227,"Not Started")
A8: SKIPPED | E8: NEEDS REVISIT | I8: % COMPLETE | M8: MUST-DO % COMPLETE
A9: =COUNTIF('Study Plan'!$I$2:$I$227,"Skipped") | E9: =COUNTIF('Study Plan'!$J$2:$J$227,"Yes") | I9: =IFERROR(E5/A5,0) | M9: =IFERROR((COUNTIFS('Study Plan'!$F$2:$F$227,"Must-do",'Study Plan'!$I$2:$I$227,"Solved"))/(COUNTIF('Study Plan'!$F$2:$F$227,"Must-do")),0)
A13: Snapshot | D13: Phase | E13: Total | F13: Solved | G13: In Progress | H13: Skipped | I13: Not Started | J13: Needs Revisit | K13: % Complete
A14: Must-do Problems | B14: =COUNTIF('Study Plan'!$F$2:$F$227,"Must-do") | D14: Phase 1 · Foundations | E14: =COUNTIF('Study Plan'!$B$2:$B$227,D14) | F14: =COUNTIFS('Study Plan'!$B$2:$B$227,D14,'Study Plan'!$I$2:$I$227,"Solved") | G14: =COUNTIFS('Study Plan'!$B$2:$B$227,D14,'Study Plan'!$I$2:$I$227,"In Progress") | H14: =COUNTIFS('Study Plan'!$B$2:$B$227,D14,'Study Plan'!$I$2:$I$227,"Skipped") | I14: =COUNTIFS('Study Plan'!$B$2:$B$227,D14,'Study Plan'!$I$2:$I$227,"Not Started") | J14: =COUNTIFS('Study Plan'!$B$2:$B$227,D14,'Study Plan'!$J$2:$J$227,"Yes") | K14: =IFERROR(F14/E14,0)
A15: Must-do Solved | B15: =COUNTIFS('Study Plan'!$F$2:$F$227,"Must-do",'Study Plan'!$I$2:$I$227,"Solved") | D15: Phase 2 · Structures & Idioms | E15: =COUNTIF('Study Plan'!$B$2:$B$227,D15) | F15: =COUNTIFS('Study Plan'!$B$2:$B$227,D15,'Study Plan'!$I$2:$I$227,"Solved") | G15: =COUNTIFS('Study Plan'!$B$2:$B$227,D15,'Study Plan'!$I$2:$I$227,"In Progress") | H15: =COUNTIFS('Study Plan'!$B$2:$B$227,D15,'Study Plan'!$I$2:$I$227,"Skipped") | I15: =COUNTIFS('Study Plan'!$B$2:$B$227,D15,'Study Plan'!$I$2:$I$227,"Not Started") | J15: =COUNTIFS('Study Plan'!$B$2:$B$227,D15,'Study Plan'!$J$2:$J$227,"Yes") | K15: =IFERROR(F15/E15,0)
A16: Solved — Last 7 Days | B16: =COUNTIFS('Study Plan'!$I$2:$I$227,"Solved",'Study Plan'!$K$2:$K$227,">="&TODAY()-7) | D16: Phase 3 · Trees & Graphs | E16: =COUNTIF('Study Plan'!$B$2:$B$227,D16) | F16: =COUNTIFS('Study Plan'!$B$2:$B$227,D16,'Study Plan'!$I$2:$I$227,"Solved") | G16: =COUNTIFS('Study Plan'!$B$2:$B$227,D16,'Study Plan'!$I$2:$I$227,"In Progress") | H16: =COUNTIFS('Study Plan'!$B$2:$B$227,D16,'Study Plan'!$I$2:$I$227,"Skipped") | I16: =COUNTIFS('Study Plan'!$B$2:$B$227,D16,'Study Plan'!$I$2:$I$227,"Not Started") | J16: =COUNTIFS('Study Plan'!$B$2:$B$227,D16,'Study Plan'!$J$2:$J$227,"Yes") | K16: =IFERROR(F16/E16,0)
A17: Solved — Last 30 Days | B17: =COUNTIFS('Study Plan'!$I$2:$I$227,"Solved",'Study Plan'!$K$2:$K$227,">="&TODAY()-30) | D17: Phase 4 · Optimization & Advanced | E17: =COUNTIF('Study Plan'!$B$2:$B$227,D17) | F17: =COUNTIFS('Study Plan'!$B$2:$B$227,D17,'Study Plan'!$I$2:$I$227,"Solved") | G17: =COUNTIFS('Study Plan'!$B$2:$B$227,D17,'Study Plan'!$I$2:$I$227,"In Progress") | H17: =COUNTIFS('Study Plan'!$B$2:$B$227,D17,'Study Plan'!$I$2:$I$227,"Skipped") | I17: =COUNTIFS('Study Plan'!$B$2:$B$227,D17,'Study Plan'!$I$2:$I$227,"Not Started") | J17: =COUNTIFS('Study Plan'!$B$2:$B$227,D17,'Study Plan'!$J$2:$J$227,"Yes") | K17: =IFERROR(F17/E17,0)
A18: Last Solved Date | B18: =IFERROR(MAX('Study Plan'!$K$2:$K$227),"—") | D18: GRAND TOTAL | E18: =SUM(E14:E17) | F18: =SUM(F14:F17) | G18: =SUM(G14:G17) | H18: =SUM(H14:H17) | I18: =SUM(I14:I17) | J18: =SUM(J14:J17) | K18: =IFERROR(F18/E18,0)
A19: Days Since Last Solved | B19: =IFERROR(TODAY()-B18,"—")

Sheet Topic Pipeline
A1: Phase | B1: Topic | C1: Not Started | D1: In Progress | E1: Skipped | F1: Needs Revisit | G1: Solved | H1: Total | I1: % Complete | J1: Must-do Total | K1: Must-do Solved | L1: Must-do %
A2: Phase 1 · Foundations | B2: 📦 Arrays & Matrices | C2: =COUNTIFS('Study Plan'!$C$2:$C$227,B2,'Study Plan'!$I$2:$I$227,"Not Started") | D2: =COUNTIFS('Study Plan'!$C$2:$C$227,B2,'Study Plan'!$I$2:$I$227,"In Progress") | E2: =COUNTIFS('Study Plan'!$C$2:$C$227,B2,'Study Plan'!$I$2:$I$227,"Skipped") | F2: =COUNTIFS('Study Plan'!$C$2:$C$227,B2,'Study Plan'!$J$2:$J$227,"Yes") | G2: =COUNTIFS('Study Plan'!$C$2:$C$227,B2,'Study Plan'!$I$2:$I$227,"Solved") | H2: =COUNTIF('Study Plan'!$C$2:$C$227,B2) | I2: =IFERROR(G2/H2,0) | J2: =COUNTIFS('Study Plan'!$C$2:$C$227,B2,'Study Plan'!$F$2:$F$227,"Must-do") | K2: =COUNTIFS('Study Plan'!$C$2:$C$227,B2,'Study Plan'!$F$2:$F$227,"Must-do",'Study Plan'!$I$2:$I$227,"Solved") | L2: =IFERROR(K2/J2,0)
A3: Phase 1 · Foundations | B3: 📊 1-D & 2-D Arrays | C3: =COUNTIFS('Study Plan'!$C$2:$C$227,B3,'Study Plan'!$I$2:$I$227,"Not Started") | D3: =COUNTIFS('Study Plan'!$C$2:$C$227,B3,'Study Plan'!$I$2:$I$227,"In Progress") | E3: =COUNTIFS('Study Plan'!$C$2:$C$227,B3,'Study Plan'!$I$2:$I$227,"Skipped") | F3: =COUNTIFS('Study Plan'!$C$2:$C$227,B3,'Study Plan'!$J$2:$J$227,"Yes") | G3: =COUNTIFS('Study Plan'!$C$2:$C$227,B3,'Study Plan'!$I$2:$I$227,"Solved") | H3: =COUNTIF('Study Plan'!$C$2:$C$227,B3) | I3: =IFERROR(G3/H3,0) | J3: =COUNTIFS('Study Plan'!$C$2:$C$227,B3,'Study Plan'!$F$2:$F$227,"Must-do") | K3: =COUNTIFS('Study Plan'!$C$2:$C$227,B3,'Study Plan'!$F$2:$F$227,"Must-do",'Study Plan'!$I$2:$I$227,"Solved") | L3: =IFERROR(K3/J3,0)
A4: Phase 1 · Foundations | B4: 🔍 Two Pointers | C4: =COUNTIFS('Study Plan'!$C$2:$C$227,B4,'Study Plan'!$I$2:$I$227,"Not Started") | D4: =COUNTIFS('Study Plan'!$C$2:$C$227,B4,'Study Plan'!$I$2:$I$227,"In Progress") | E4: =COUNTIFS('Study Plan'!$C$2:$C$227,B4,'Study Plan'!$I$2:$I$227,"Skipped") | F4: =COUNTIFS('Study Plan'!$C$2:$C$227,B4,'Study Plan'!$J$2:$J$227,"Yes") | G4: =COUNTIFS('Study Plan'!$C$2:$C$227,B4,'Study Plan'!$I$2:$I$227,"Solved") | H4: =COUNTIF('Study Plan'!$C$2:$C$227,B4) | I4: =IFERROR(G4/H4,0) | J4: =COUNTIFS('Study Plan'!$C$2:$C$227,B4,'Study Plan'!$F$2:$F$227,"Must-do") | K4: =COUNTIFS('Study Plan'!$C$2:$C$227,B4,'Study Plan'!$F$2:$F$227,"Must-do",'Study Plan'!$I$2:$I$227,"Solved") | L4: =IFERROR(K4/J4,0)
A5: Phase 1 · Foundations | B5: 🧮 Hashing / Sliding Window | C5: =COUNTIFS('Study Plan'!$C$2:$C$227,B5,'Study Plan'!$I$2:$I$227,"Not Started") | D5: =COUNTIFS('Study Plan'!$C$2:$C$227,B5,'Study Plan'!$I$2:$I$227,"In Progress") | E5: =COUNTIFS('Study Plan'!$C$2:$C$227,B5,'Study Plan'!$I$2:$I$227,"Skipped") | F5: =COUNTIFS('Study Plan'!$C$2:$C$227,B5,'Study Plan'!$J$2:$J$227,"Yes") | G5: =COUNTIFS('Study Plan'!$C$2:$C$227,B5,'Study Plan'!$I$2:$I$227,"Solved") | H5: =COUNTIF('Study Plan'!$C$2:$C$227,B5) | I5: =IFERROR(G5/H5,0) | J5: =COUNTIFS('Study Plan'!$C$2:$C$227,B5,'Study Plan'!$F$2:$F$227,"Must-do") | K5: =COUNTIFS('Study Plan'!$C$2:$C$227,B5,'Study Plan'!$F$2:$F$227,"Must-do",'Study Plan'!$I$2:$I$227,"Solved") | L5: =IFERROR(K5/J5,0)
A6: Phase 1 · Foundations | B6: 📚 Stack | C6: =COUNTIFS('Study Plan'!$C$2:$C$227,B6,'Study Plan'!$I$2:$I$227,"Not Started") | D6: =COUNTIFS('Study Plan'!$C$2:$C$227,B6,'Study Plan'!$I$2:$I$227,"In Progress") | E6: =COUNTIFS('Study Plan'!$C$2:$C$227,B6,'Study Plan'!$I$2:$I$227,"Skipped") | F6: =COUNTIFS('Study Plan'!$C$2:$C$227,B6,'Study Plan'!$J$2:$J$227,"Yes") | G6: =COUNTIFS('Study Plan'!$C$2:$C$227,B6,'Study Plan'!$I$2:$I$227,"Solved") | H6: =COUNTIF('Study Plan'!$C$2:$C$227,B6) | I6: =IFERROR(G6/H6,0) | J6: =COUNTIFS('Study Plan'!$C$2:$C$227,B6,'Study Plan'!$F$2:$F$227,"Must-do") | K6: =COUNTIFS('Study Plan'!$C$2:$C$227,B6,'Study Plan'!$F$2:$F$227,"Must-do",'Study Plan'!$I$2:$I$227,"Solved") | L6: =IFERROR(K6/J6,0)
A7: Phase 1 · Foundations | B7: 🔗 Linked List | C7: =COUNTIFS('Study Plan'!$C$2:$C$227,B7,'Study Plan'!$I$2:$I$227,"Not Started") | D7: =COUNTIFS('Study Plan'!$C$2:$C$227,B7,'Study Plan'!$I$2:$I$227,"In Progress") | E7: =COUNTIFS('Study Plan'!$C$2:$C$227,B7,'Study Plan'!$I$2:$I$227,"Skipped") | F7: =COUNTIFS('Study Plan'!$C$2:$C$227,B7,'Study Plan'!$J$2:$J$227,"Yes") | G7: =COUNTIFS('Study Plan'!$C$2:$C$227,B7,'Study Plan'!$I$2:$I$227,"Solved") | H7: =COUNTIF('Study Plan'!$C$2:$C$227,B7) | I7: =IFERROR(G7/H7,0) | J7: =COUNTIFS('Study Plan'!$C$2:$C$227,B7,'Study Plan'!$F$2:$F$227,"Must-do") | K7: =COUNTIFS('Study Plan'!$C$2:$C$227,B7,'Study Plan'!$F$2:$F$227,"Must-do",'Study Plan'!$I$2:$I$227,"Solved") | L7: =IFERROR(K7/J7,0)
A8: Phase 1 · Foundations | B8: 🔍 Searching / Binary Search | C8: =COUNTIFS('Study Plan'!$C$2:$C$227,B8,'Study Plan'!$I$2:$I$227,"Not Started") | D8: =COUNTIFS('Study Plan'!$C$2:$C$227,B8,'Study Plan'!$I$2:$I$227,"In Progress") | E8: =COUNTIFS('Study Plan'!$C$2:$C$227,B8,'Study Plan'!$I$2:$I$227,"Skipped") | F8: =COUNTIFS('Study Plan'!$C$2:$C$227,B8,'Study Plan'!$J$2:$J$227,"Yes") | G8: =COUNTIFS('Study Plan'!$C$2:$C$227,B8,'Study Plan'!$I$2:$I$227,"Solved") | H8: =COUNTIF('Study Plan'!$C$2:$C$227,B8) | I8: =IFERROR(G8/H8,0) | J8: =COUNTIFS('Study Plan'!$C$2:$C$227,B8,'Study Plan'!$F$2:$F$227,"Must-do") | K8: =COUNTIFS('Study Plan'!$C$2:$C$227,B8,'Study Plan'!$F$2:$F$227,"Must-do",'Study Plan'!$I$2:$I$227,"Solved") | L8: =IFERROR(K8/J8,0)
A9: Phase 2 · Structures & Idioms | B9: ➗ Math | C9: =COUNTIFS('Study Plan'!$C$2:$C$227,B9,'Study Plan'!$I$2:$I$227,"Not Started") | D9: =COUNTIFS('Study Plan'!$C$2:$C$227,B9,'Study Plan'!$I$2:$I$227,"In Progress") | E9: =COUNTIFS('Study Plan'!$C$2:$C$227,B9,'Study Plan'!$I$2:$I$227,"Skipped") | F9: =COUNTIFS('Study Plan'!$C$2:$C$227,B9,'Study Plan'!$J$2:$J$227,"Yes") | G9: =COUNTIFS('Study Plan'!$C$2:$C$227,B9,'Study Plan'!$I$2:$I$227,"Solved") | H9: =COUNTIF('Study Plan'!$C$2:$C$227,B9) | I9: =IFERROR(G9/H9,0) | J9: =COUNTIFS('Study Plan'!$C$2:$C$227,B9,'Study Plan'!$F$2:$F$227,"Must-do") | K9: =COUNTIFS('Study Plan'!$C$2:$C$227,B9,'Study Plan'!$F$2:$F$227,"Must-do",'Study Plan'!$I$2:$I$227,"Solved") | L9: =IFERROR(K9/J9,0)
A10: Phase 2 · Structures & Idioms | B10: 🧮 Bit Manipulation | C10: =COUNTIFS('Study Plan'!$C$2:$C$227,B10,'Study Plan'!$I$2:$I$227,"Not Started") | D10: =COUNTIFS('Study Plan'!$C$2:$C$227,B10,'Study Plan'!$I$2:$I$227,"In Progress") | E10: =COUNTIFS('Study Plan'!$C$2:$C$227,B10,'Study Plan'!$I$2:$I$227,"Skipped") | F10: =COUNTIFS('Study Plan'!$C$2:$C$227,B10,'Study Plan'!$J$2:$J$227,"Yes") | G10: =COUNTIFS('Study Plan'!$C$2:$C$227,B10,'Study Plan'!$I$2:$I$227,"Solved") | H10: =COUNTIF('Study Plan'!$C$2:$C$227,B10) | I10: =IFERROR(G10/H10,0) | J10: =COUNTIFS('Study Plan'!$C$2:$C$227,B10,'Study Plan'!$F$2:$F$227,"Must-do") | K10: =COUNTIFS('Study Plan'!$C$2:$C$227,B10,'Study Plan'!$F$2:$F$227,"Must-do",'Study Plan'!$I$2:$I$227,"Solved") | L10: =IFERROR(K10/J10,0)
A11: Phase 2 · Structures & Idioms | B11: 🚦 Queues / Deque / Monotonic Queue | C11: =COUNTIFS('Study Plan'!$C$2:$C$227,B11,'Study Plan'!$I$2:$I$227,"Not Started") | D11: =COUNTIFS('Study Plan'!$C$2:$C$227,B11,'Study Plan'!$I$2:$I$227,"In Progress") | E11: =COUNTIFS('Study Plan'!$C$2:$C$227,B11,'Study Plan'!$I$2:$I$227,"Skipped") | F11: =COUNTIFS('Study Plan'!$C$2:$C$227,B11,'Study Plan'!$J$2:$J$227,"Yes") | G11: =COUNTIFS('Study Plan'!$C$2:$C$227,B11,'Study Plan'!$I$2:$I$227,"Solved") | H11: =COUNTIF('Study Plan'!$C$2:$C$227,B11) | I11: =IFERROR(G11/H11,0) | J11: =COUNTIFS('Study Plan'!$C$2:$C$227,B11,'Study Plan'!$F$2:$F$227,"Must-do") | K11: =COUNTIFS('Study Plan'!$C$2:$C$227,B11,'Study Plan'!$F$2:$F$227,"Must-do",'Study Plan'!$I$2:$I$227,"Solved") | L11: =IFERROR(K11/J11,0)
A12: Phase 2 · Structures & Idioms | B12: 🔄 Sorting / Divide & Conquer | C12: =COUNTIFS('Study Plan'!$C$2:$C$227,B12,'Study Plan'!$I$2:$I$227,"Not Started") | D12: =COUNTIFS('Study Plan'!$C$2:$C$227,B12,'Study Plan'!$I$2:$I$227,"In Progress") | E12: =COUNTIFS('Study Plan'!$C$2:$C$227,B12,'Study Plan'!$I$2:$I$227,"Skipped") | F12: =COUNTIFS('Study Plan'!$C$2:$C$227,B12,'Study Plan'!$J$2:$J$227,"Yes") | G12: =COUNTIFS('Study Plan'!$C$2:$C$227,B12,'Study Plan'!$I$2:$I$227,"Solved") | H12: =COUNTIF('Study Plan'!$C$2:$C$227,B12) | I12: =IFERROR(G12/H12,0) | J12: =COUNTIFS('Study Plan'!$C$2:$C$227,B12,'Study Plan'!$F$2:$F$227,"Must-do") | K12: =COUNTIFS('Study Plan'!$C$2:$C$227,B12,'Study Plan'!$F$2:$F$227,"Must-do",'Study Plan'!$I$2:$I$227,"Solved") | L12: =IFERROR(K12/J12,0)
A13: Phase 2 · Structures & Idioms | B13: 🔁 Recursion | C13: =COUNTIFS('Study Plan'!$C$2:$C$227,B13,'Study Plan'!$I$2:$I$227,"Not Started") | D13: =COUNTIFS('Study Plan'!$C$2:$C$227,B13,'Study Plan'!$I$2:$I$227,"In Progress") | E13: =COUNTIFS('Study Plan'!$C$2:$C$227,B13,'Study Plan'!$I$2:$I$227,"Skipped") | F13: =COUNTIFS('Study Plan'!$C$2:$C$227,B13,'Study Plan'!$J$2:$J$227,"Yes") | G13: =COUNTIFS('Study Plan'!$C$2:$C$227,B13,'Study Plan'!$I$2:$I$227,"Solved") | H13: =COUNTIF('Study Plan'!$C$2:$C$227,B13) | I13: =IFERROR(G13/H13,0) | J13: =COUNTIFS('Study Plan'!$C$2:$C$227,B13,'Study Plan'!$F$2:$F$227,"Must-do") | K13: =COUNTIFS('Study Plan'!$C$2:$C$227,B13,'Study Plan'!$F$2:$F$227,"Must-do",'Study Plan'!$I$2:$I$227,"Solved") | L13: =IFERROR(K13/J13,0)
... A23: Phase 4 · Optimization & Advanced | B23: 🔢 Number Theory / Misc | C23: =COUNTIFS('Study Plan'!$C$2:$C$227,B23,'Study Plan'!$I$2:$I$227,"Not Started") | D23: =COUNTIFS('Study Plan'!$C$2:$C$227,B23,'Study Plan'!$I$2:$I$227,"In Progress") | E23: =COUNTIFS('Study Plan'!$C$2:$C$227,B23,'Study Plan'!$I$2:$I$227,"Skipped") | F23: =COUNTIFS('Study Plan'!$C$2:$C$227,B23,'Study Plan'!$J$2:$J$227,"Yes") | G23: =COUNTIFS('Study Plan'!$C$2:$C$227,B23,'Study Plan'!$I$2:$I$227,"Solved") | H23: =COUNTIF('Study Plan'!$C$2:$C$227,B23) | I23: =IFERROR(G23/H23,0) | J23: =COUNTIFS('Study Plan'!$C$2:$C$227,B23,'Study Plan'!$F$2:$F$227,"Must-do") | K23: =COUNTIFS('Study Plan'!$C$2:$C$227,B23,'Study Plan'!$F$2:$F$227,"Must-do",'Study Plan'!$I$2:$I$227,"Solved") | L23: =IFERROR(K23/J23,0)
B24: GRAND TOTAL (22 topics) | C24: =SUM(C2:C23) | D24: =SUM(D2:D23) | E24: =SUM(E2:E23) | F24: =SUM(F2:F23) | G24: =SUM(G2:G23) | H24: =SUM(H2:H23) | I24: =IFERROR(G24/H24,0) | J24: =SUM(J2:J23) | K24: =SUM(K2:K23) | L24: =IFERROR(K24/J24,0)

Sheet Pending Queue
A1: 🟠 Pending Queue — Not Started + In Progress, in study order
A2: Dynamic — FILTER() pulled live from 'Study Plan'. Skipped problems are excluded on purpose; see the Skipped tab.
A3: # | B3: Phase | C3: Topic | D3: Sub-Pattern | E3: Topic Order# | F3: Priority | G3: Problem | H3: Pattern / Approach Note | I3: Status | J3: Needs Revisit | K3: Date Solved | L3: Notes | M3: LeetCode Link | N3: Walkthrough
A4: =IFERROR(FILTER('Study Plan'!$A$2:$N$227,('Study Plan'!$I$2:$I$227="Not Started")+('Study Plan'!$I$2:$I$227="In Progress")),"Nothing pending — every problem has been started or solved. 🎉")

Sheet Revisit Queue
A1: 🔁 Revisit Queue — flagged for a second pass (independent of Status)
A2: Dynamic — a problem can be Solved AND still show up here if Needs Revisit = Yes.
A3: # | B3: Phase | C3: Topic | D3: Sub-Pattern | E3: Topic Order# | F3: Priority | G3: Problem | H3: Pattern / Approach Note | I3: Status | J3: Needs Revisit | K3: Date Solved | L3: Notes | M3: LeetCode Link | N3: Walkthrough
A4: =IFERROR(FILTER('Study Plan'!$A$2:$N$227,'Study Plan'!$J$2:$J$227="Yes"),"Nothing marked Needs Revisit right now. 🎉")

Sheet Skipped
A1: ⏭️ Skipped — deliberately not attempted
A2: Dynamic — problems whose Status is Skipped. Kept separate from Not Started since these were a deliberate call, not a backlog.
A3: # | B3: Phase | C3: Topic | D3: Sub-Pattern | E3: Topic Order# | F3: Priority | G3: Problem | H3: Pattern / Approach Note | I3: Status | J3: Needs Revisit | K3: Date Solved | L3: Notes | M3: LeetCode Link | N3: Walkthrough
A4: =IFERROR(FILTER('Study Plan'!$A$2:$N$227,'Study Plan'!$I$2:$I$227="Skipped"),"Nothing marked Skipped right now.")

Sheet Data Issues (source xlsx)
A1: Issue | B1: Row A | C1: Row B
A2: Duplicate problem entry in current_progress.xlsx | B2: S.No 20.0: Number of Operations to Make Network Connected (https://leetcode.com/problems/number-of-operations-to-make-network-connected/) | C2: S.No 44.0: Number of Operations to Make Network Connected (https://leetcode.com/problems/number-of-operations-to-make-network-connected/description/)
A3: Duplicate problem entry in current_progress.xlsx | B3: S.No 153.0: Count Substrings That Differ by One Character (https://leetcode.com/problems/count-substrings-that-differ-by-one-character/) | C3: S.No 155.0: Count Substrings That Differ by One Character (https://leetcode.com/problems/count-substrings-that-differ-by-one-character/description/)
A4: Duplicate problem entry in current_progress.xlsx | B4: S.No 171.0: Unique Binary Search Trees (https://leetcode.com/problems/unique-binary-search-trees/) | C4: S.No 182.0: Unique Binary Search Trees (https://leetcode.com/problems/unique-binary-search-trees/)
A5: Duplicate problem entry in current_progress.xlsx | B5: S.No 175.0: Numbers at Most N Given Digit Set (https://leetcode.com/problems/numbers-at-most-n-given-digit-set/) | C5: S.No 183.0: Numbers At Most N Given Digit Set (https://leetcode.com/problems/numbers-at-most-n-given-digit-set/description/)
A6: Free-text note preserved from source Notes column | B6: Number of Provinces | C6: This is a variation of DFS
A7: Free-text note preserved from source Notes column | B7: Binary Tree Left Side View | C7: Question is removed from LeetCode
A8: Free-text note preserved from source Notes column | B8: Construct Binary Tree from Traversals | C8: Repeated question
A10: Note: duplicates are de-duplicated automatically in Study Plan. 'Revisit' and 'Skipped' values that used to live in the Notes column are now modeled as Needs Revisit / Status = Skipped instead.
